Workbook
Name Anonymise: 'Labels'!$B$12
Name Label_Key: 'Labels'!$A$2:$A$10
Name Label_Anon: 'Labels'!$B$2:$B$10
Name Label_Real: 'Labels'!$C$2:$C$10
Name Scenario: 'Assumptions'!$C$5
Name Consultant_Present: 'Assumptions'!$C$7
Name Resp_Internal: 'Assumptions'!$C$8
Name Efficiency: 'Assumptions'!$C$9
Name Extra_Ops_Fte: 'Assumptions'!$C$10
Name Seat_Ops_Alloc: 'Assumptions'!$C$11
Name As_Of: 'Assumptions'!$C$12
Name Horizon: 'Assumptions'!$C$13
Name Benefits_Load: 'Assumptions'!$C$16
Name Productive_Hours: 'Assumptions'!$C$17
Name Growth_Rate: 'Assumptions'!$C$18
Name Switching_Uplift: 'Assumptions'!$C$19
Name Firm_Overhead_PH: 'Assumptions'!$C$20
Name Fee_Realisation: 'Assumptions'!$C$21
Name Departure_Days: 'Assumptions'!$C$22
Name Ops_Seat_Comp: 'Assumptions'!$C$23
Name Backfill_Cost: 'Assumptions'!$C$24
Name Failure_Cost: 'Assumptions'!$C$25
Name Failures_Avoided: 'Assumptions'!$C$26
Name Para_Backfill_Comp: 'Assumptions'!$C$27
Name Advisor_Basis: 'Assumptions'!$C$28
Name Roster_Active: 'Roster'!$K$2:$K$8
Name Roster_Adv: 'Roster'!$D$2:$D$8
Name Roster_FTE: 'Roster'!$C$2:$C$8
Name Roster_Loaded: 'Roster'!$N$2:$N$8
Name Roster_Hourly: 'Roster'!$O$2:$O$8
Name Roster_OpsHours: 'Roster'!$P$2:$P$8
Name Ops_Hours_Available: 'Roster'!$P$10
Name Total_FTE: 'Roster'!$C$10
Name Total_HH: 'Book'!$C$6
Name Book_HH: 'Book'!$C$2:$C$5
Name Book_AvgAum: 'Book'!$D$2:$D$5
Name Book_Acct: 'Book'!$E$2:$E$5
Name Book_Mix: 'Book'!$F$2:$F$5
Name Book_HHAcct: 'Book'!$I$2:$I$5
Name Book_New: 'Book'!$J$2:$J$5
Name Book_RevPH: 'Book'!$L$2:$L$5
Name Revenue_Total: 'Book'!$M$6
Name AUM_Total: 'Book'!$H$6
Name Fee_From: 'FeeSchedule'!$B$2:$B$6
Name Fee_To: 'FeeSchedule'!$C$2:$C$6
Name Fee_Rate: 'FeeSchedule'!$D$2:$D$6
Name Fee_Delta: 'FeeSchedule'!$E$2:$E$6
Name Tasks_Basis: 'Tasks'!$C$2:$C$42
Name Tasks_Min: 'Tasks'!$D$2:$D$42
Name Tasks_Occ: 'Tasks'!$E$2:$E$42
Name Tasks_A1: 'Tasks'!$F$2:$F$42
Name Tasks_A2: 'Tasks'!$G$2:$G$42
Name Tasks_A3: 'Tasks'!$H$2:$H$42
Name Tasks_A4: 'Tasks'!$I$2:$I$42
Name Tasks_Owner: 'Tasks'!$J$2:$J$42
Name Tasks_WT: 'Tasks'!$K$2:$K$42
Name Tasks_Tag: 'Tasks'!$L$2:$L$42
Name Tasks_Hours: 'Tasks'!$N$2:$N$42
Name Ledger_Tags: 'Assumptions'!$E$16:$E$93
Name Ledger_Count: 'Assumptions'!$C$95

Sheet README
B2: Operations capacity & economics model
B3: Working model · as of 2026-09-05 · schema 1.0.0
B5: What this is
C6: A model of how much operations work the firm carries, who carries it, what it costs, and when it runs out of room.
C7: Built by the paraplanner (role R4) as a working tool, not a firm document. It is the same engine as the interactive page — both are generated from one inputs file, so they cannot disagree.
B8: Who to correct it | C8: Everything in here is meant to be argued with. Change any blue or yellow cell and the whole workbook recalculates.
B10: The colour key
B11: Blue text on cream | C11: A typed input. This is a number somebody chose. Change these.
B12: Blue text on yellow | C12: A key assumption or a placeholder that still needs a real value. Change these first.
B13: Green text | C13: A link to a value on another sheet. Do not overwrite.
B14: Black text, white | C14: A formula. Do not overwrite — it will stop recalculating.
B15: Red text | C15: A figure that is currently built on a placeholder, or a result that needs attention.
B17: What is measured and what is not
C18: Every input carries a provenance tag. Of 0 inputs, most are still PLACEHOLDER — numbers invented so the model would run end to end. See the Assumptions tab; the tag column is the whole point of this workbook.
B19: MEASURED | C19: I timed it or counted it myself. Strongest evidence in the model.
B20: OBSERVED | C20: I can see it in a firm system, or I was told it directly.
B21: BENCHMARK | C21: Published industry source, cited with source and year.
B22: ESTIMATED | C22: My own judgement, stated as a range.
B23: PLACEHOLDER | C23: Not yet filled in. The model runs, but this number is fake. Treat any figure resting on one as a structure, not a finding.
B25: How to change the fee schedule
B26: 1 | C26: Go to the FeeSchedule tab. Each row is one band: the amount it starts at, the amount it ends at, and the rate charged on the portion of assets inside it.
B27: 2 | C27: Edit From / To / Rate, or add a row. If you add one, extend the named range Fee_From, Fee_To, Fee_Rate and Fee_Delta to include it.
B28: 3 | C28: The schedule is TIERED (marginal): each band charges its own rate on its own slice, not one rate on the whole balance.
B29: 4 | C29: The tab carries three hand-worked test households. If those three stop matching the hand column, the schedule has been broken — most likely by turning it into a flat rate by accident.
B31: How to switch scenario
B32: Assumptions!C5 | C32: One cell drives everything. 1 = Today · 2 = She's gone, nothing changes · 3 = She's gone, I own operations.
C33: Every case tab reads that cell. Nothing else needs changing to move between the three.
B35: Rules this model runs under
B36: No client data | C36: Counts, tiers, ranges and averages only. No names, no account numbers, no balances, no statements. The smallest unit anywhere in it is a tier.
B37: Not a compliance opinion | C37: Compliance ownership stays with the firm's designated person. Where this counts minutes on a compliance task it is counting minutes, not judging adequacy.
B38: No credentials | C38: No password, login or vendor credential appears anywhere in this workbook, and none should ever be added.
B39: Labels | C39: Role labels come from the Labels tab. Fill in the 'Real' column there for internal use; the published version of this model uses the anonymous column only.
B41: Tab order
B42: Assumptions | C42: The ledger. Every input, its value, its tag, where it came from, who could confirm it, when it was last checked.
B43: Labels | C43: Role labels. The single place names live.
B44: Roster | C44: Input: who is here, at what FTE, on what compensation, and how much of their time is operations.
B45: Book | C45: Input: households and average AUM by tier. Never per household.
B46: FeeSchedule | C46: Input: the tiered fee bands, plus three hand-worked test households.
B47: Tasks | C47: Input: the operations task catalogue. Minutes and occurrences. This is the heart of the model.
B48: Engine | C48: All calculations. No typed numbers anywhere on this sheet.
...

Sheet Labels
A1: Key | B1: Anonymous label | C1: Real label (fill in for internal use only)
A2: firm | B2: The firm | C2: The firm
A3: custodian | B3: The custodian | C3: The custodian
A4: R1 | B4: Advisor 1 (principal) | C4: Advisor 1 (principal)
A5: R2 | B5: Advisor 2 | C5: Advisor 2
A6: R3 | B6: Advisor 3 | C6: Advisor 3
A7: R4 | B7: Paraplanner (me) | C7: Paraplanner (me)
A8: R5 | B8: Client service associate | C8: Client service associate
A9: R6 | B9: Office manager | C9: Office manager
A10: R7 | B10: Operations consultant | C10: Operations consultant
A12: ANONYMISE | B12: 1 | C12: 1 = use the anonymous column everywhere · 0 = use the real column. Ships as 1.

Sheet Assumptions
A1: ASSUMPTION LEDGER
A2: Every input in the model. If a number anywhere else is wrong, it is wrong here first.
A4: SCENARIO SWITCH — this one cell drives every case tab
B5: Scenario | C5: 1 | F5: 1 = Today · 2 = She's gone, nothing changes · 3 = She's gone, I own operations
B6: Scenario name | C6: =IF(Scenario=1,"Today",IF(Scenario=2,"She's gone, nothing changes","She's gone, I own operations")) | F6: Reads the switch above.
B7: Consultant on the roster | C7: =IF(Scenario=1,1,0) | F7: 1 = still here. Drives the Roster active flag.
B8: I take the operations seat | C8: =IF(Scenario=3,1,0) | F8: 1 = my row moves to the operations allocation and compensation below.
B9: Minutes per task (efficiency) | C9: 1 | F9: Global multiplier on every task timing. 90% is a 10% process improvement.
B10: Extra operations FTE | C10: 0 | F10: Additive only in the workbook. Use it to test a hire.
B11: My operations share if I take the seat | C11: 0.85 | F11: Case 4. The rest of my week stays paraplanning.
B12: As of | C12: 46270 | F12: Every projected date counts forward from here.
B13: Projection horizon (months) | C13: 72 | F13: Length of the capacity projection on Case2.
A15: Ref | B15: Input | C15: Value | D15: Unit | E15: Tag | F15: Where it came from | G15: Who could confirm it | H15: Last checked
A16: C-1 | B16: Benefits and payroll load | C16: 0.25 | D16: pct | E16: BENCHMARK | F16: US Bureau of Labor Statistics, Employer Costs for Employee Compensation. Benefits run about 29-31% of total compensation for private industry, i.e. roughly a 40-45% load on wages; finance and insurance sits near the top of that band. 25% is a deliberately conservative load covering payroll taxes, health and retirement only. | G16: The principal, or whoever handles payroll, can give the real loaded figure. | H16: 2026-09-05
A17: C-2 | B17: Productive hours per person per year | C17: 1700 | D17: hours | E17: ESTIMATED | F17: 2,080 scheduled hours less PTO, holidays, sick time, training and internal admin. Range I would defend: 1,600-1,800. | G17: The principal can confirm the PTO and holiday policy; the rest is my judgement. | H17: 2026-09-05
A18: C-3 | B18: Household growth rate per year | C18: 0.15 | D18: pct | E18: ESTIMATED | F18: My impression of the last few quarters of new-client activity. Not verified against a count. | G18: The principal, or a new-account count out of the CRM for the last three years. | H18: 2026-09-05
A19: C-4 | B19: Switching and interruption uplift | C19: 0.25 | D19: pct | E19: ESTIMATED | F19: A timed task measures the task, not the day. Real operations days carry context-switching, interruptions, rework and queue time that no task timing captures. 25% is my judgement; range 15-40%. Set it to 0% to see catalogued task time alone. | G19: Nobody can confirm this directly. It is the assumption most worth arguing about. | H19: 2026-09-05
A20: C-5 | B20: Non-payroll firm overhead per household per year | C20: 1800 | D20: usd | E20: PLACEHOLDER | F20: NOT FILLED IN. Should cover rent, technology stack, custodial platform fees, E&O, compliance vendors, professional fees, marketing, divided by household count. I cannot see the expense lines. | G20: The principal. This is the single number that decides whether the bottom tier looks profitable or not - do not present tier economics without it. | H20: never
A21: C-6 | B21: Fee realisation against schedule | C21: 1 | D21: pct | E21: PLACEHOLDER | F21: NOT FILLED IN. Assumed every household pays the published schedule with no discount, no family aggregation and no flat-fee exception. That is almost certainly not true. | G21: The billing run from the last quarterly cycle: actual fees billed divided by fees the schedule implies. | H21: never
A22: C-7 | B22: Days until the operations consultant leaves | C22: 100 | D22: days | E22: OBSERVED | F22: Told to me directly. | G22: The principal. | H22: 2026-09-05
A23: C-8 | B23: Compensation for an operations manager seat | C23: 92000 | D23: usd | E23: PLACEHOLDER | F23: NOT FILLED IN. My guess at the market rate for an operations manager at a firm this size. | G23: The principal. A compensation study (Schwab RIA Benchmarking, Investment News Adviser Compensation) would give a defensible band. | H23: never
A24: C-9 | B24: Annual cost to backfill the consultant like-for-like | C24: 78000 | D24: usd | E24: PLACEHOLDER | F24: NOT FILLED IN. Assumed a replacement consultant costs what the current one costs. | G24: The principal knows the current engagement cost. A replacement quote would be a real number. | H24: never
A25: C-10 | B25: Cost of one service failure | C25: 2500 | D25: usd | E25: PLACEHOLDER | F25: NOT FILLED IN. A missed RMD penalty, a late transfer, a billing error and a blown deadline all cost different amounts. | G25: The principal, or the compliance file of past incidents. | H25: never
A26: C-11 | B26: Service failures avoided per year by the seat | C26: 0 | D26: count | E26: PLACEHOLDER | F26: DELIBERATELY ZERO. I have no incident list, so I am counting nothing. Leaving this at zero makes the case for the seat weaker and honest. Raise it only against real incidents someone can name. | G26: The principal or the consultant can name actual incidents from the last two years. | H26: never
A27: C-12 | B27: Compensation for a junior seat to absorb displaced paraplanning work | C27: 55000 | D27: usd | E27: PLACEHOLDER | F27: NOT FILLED IN. My guess at a client service or associate paraplanner salary. Only relevant if the operations seat happens and the planning work I do now has to go somewhere. | G27: The principal. | H27: never
A28: C-13 | B28: How an advisor hour is valued | C28: loaded_cost | D28: choice | E28: ESTIMATED | F28: Two options: 'loaded_cost' values a returned advisor hour at what it costs the firm (conservative, hard to argue with) or 'revenue_capacity' values it at revenue per advisor hour (larger, and it invites the challenge that the hour would not actually have been sold). Defaulting to loaded cost on purpose. | G28: This is a framing choice, not a fact. Ask the principal which he finds credible. | H28: 2026-09-05
A29: R-1 | B29: =Roster!B2&" — annual compensation" | C29: =Roster!G2 | D29: usd | E29: PLACEHOLDER | F29: NOT FILLED IN. Principal compensation is a guess and is probably wrong; owner comp is often taken as distribution rather than salary. | G29: The principal. Do not push on this one - use a range if he prefers. | H29: never
A30: R-2 | B30: =Roster!B2&" — FTE" | C30: =Roster!C2 | D30: fte | E30: OBSERVED | F30: Headcount I can see. | G30: The principal holds the contract or the offer letter. | H30: 2026-09-05
A31: R-3 | B31: =Roster!B3&" — annual compensation" | C31: =Roster!G3 | D31: usd | E31: PLACEHOLDER | F31: NOT FILLED IN. My guess. | G31: The principal. | H31: never
A32: R-4 | B32: =Roster!B3&" — FTE" | C32: =Roster!C3 | D32: fte | E32: OBSERVED | F32: Headcount I can see. | G32: The principal holds the contract or the offer letter. | H32: 2026-09-05
A33: R-5 | B33: =Roster!B4&" — annual compensation" | C33: =Roster!G4 | D33: usd | E33: PLACEHOLDER | F33: NOT FILLED IN. My guess. | G33: The principal. | H33: never
A34: R-6 | B34: =Roster!B4&" — FTE" | C34: =Roster!C4 | D34: fte | E34: OBSERVED | F34: Headcount I can see. | G34: The principal holds the contract or the offer letter. | H34: 2026-09-05
A35: R-7 | B35: =Roster!B5&" — annual compensation" | C35: =Roster!G5 | D35: usd | E35: OBSERVED | F35: My own compensation. The 35% operations allocation is my estimate of my own week; the rest is plan work and research. | G35: Me. I can make the allocation MEASURED by keeping a two-week time log. | H35: 2026-09-05
A36: R-8 | B36: =Roster!B5&" — FTE" | C36: =Roster!C5 | D36: fte | E36: OBSERVED | F36: Headcount I can see. | G36: The principal holds the contract or the offer letter. | H36: 2026-09-05
A37: R-9 | B37: =Roster!B5&" — share of time on operations" | C37: =Roster!F5 | D37: pct | E37: ESTIMATED | F37: My estimate of how much of this person's week is operations work rather than planning, bookkeeping or reception. | G37: The person themselves, from a two-week time log. The cheapest input in the model to upgrade. | H37: 2026-09-05
A38: R-10 | B38: =Roster!B6&" — annual compensation" | C38: =Roster!G6 | D38: usd | E38: PLACEHOLDER | F38: NOT FILLED IN. My guess at a client service associate salary. | G38: The principal. | H38: never
A39: R-11 | B39: =Roster!B6&" — FTE" | C39: =Roster!C6 | D39: fte | E39: OBSERVED | F39: Headcount I can see. | G39: The principal holds the contract or the offer letter. | H39: 2026-09-05
A40: R-12 | B40: =Roster!B6&" — share of time on operations" | C40: =Roster!F6 | D40: pct | E40: ESTIMATED | F40: My estimate of how much of this person's week is operations work rather than planning, bookkeeping or reception. | G40: The person themselves, from a two-week time log. The cheapest input in the model to upgrade. | H40: 2026-09-05
A41: R-13 | B41: =Roster!B7&" — annual compensation" | C41: =Roster!G7 | D41: usd | E41: PLACEHOLDER | F41: NOT FILLED IN. My guess. The 50% operations allocation excludes bookkeeping, HR, facilities and reception. | G41: The principal. | H41: never
A42: R-14 | B42: =Roster!B7&" — FTE" | C42: =Roster!C7 | D42: fte | E42: OBSERVED | F42: Headcount I can see. | G42: The principal holds the contract or the offer letter. | H42: 2026-09-05
...

Sheet Roster
A1: Role | B1: Label | C1: FTE | D1: Advisor? | E1: Operations? | F1: Ops share | G1: Compensation | H1: Comp tag | I1: Contractor? | J1: End date | K1: Active | L1: Effective ops share | M1: Effective comp | N1: Loaded cost | O1: Loaded $/hour | P1: Ops hours available
A2: R1 | B2: =IF(Anonymise=1,INDEX(Label_Anon,MATCH("R1",Label_Key,0)),INDEX(Label_Real,MATCH("R1",Label_Key,0))) | C2: 1 | D2: 1 | E2: 0 | F2: 0 | G2: 250000 | H2: PLACEHOLDER | I2: 0 | K2: =IF(A2="R7",Consultant_Present,1) | L2: =IF(AND(A2="R4",Resp_Internal=1),Seat_Ops_Alloc,F2) | M2: =IF(AND(A2="R4",Resp_Internal=1),Ops_Seat_Comp,G2) | N2: =M2*(1+IF(I2=1,0,Benefits_Load)) | O2: =IF(C2*Productive_Hours=0,0,N2/(C2*Productive_Hours)) | P2: =K2*E2*C2*L2*Productive_Hours
A3: R2 | B3: =IF(Anonymise=1,INDEX(Label_Anon,MATCH("R2",Label_Key,0)),INDEX(Label_Real,MATCH("R2",Label_Key,0))) | C3: 1 | D3: 1 | E3: 0 | F3: 0 | G3: 165000 | H3: PLACEHOLDER | I3: 0 | K3: =IF(A3="R7",Consultant_Present,1) | L3: =IF(AND(A3="R4",Resp_Internal=1),Seat_Ops_Alloc,F3) | M3: =IF(AND(A3="R4",Resp_Internal=1),Ops_Seat_Comp,G3) | N3: =M3*(1+IF(I3=1,0,Benefits_Load)) | O3: =IF(C3*Productive_Hours=0,0,N3/(C3*Productive_Hours)) | P3: =K3*E3*C3*L3*Productive_Hours
A4: R3 | B4: =IF(Anonymise=1,INDEX(Label_Anon,MATCH("R3",Label_Key,0)),INDEX(Label_Real,MATCH("R3",Label_Key,0))) | C4: 1 | D4: 1 | E4: 0 | F4: 0 | G4: 140000 | H4: PLACEHOLDER | I4: 0 | K4: =IF(A4="R7",Consultant_Present,1) | L4: =IF(AND(A4="R4",Resp_Internal=1),Seat_Ops_Alloc,F4) | M4: =IF(AND(A4="R4",Resp_Internal=1),Ops_Seat_Comp,G4) | N4: =M4*(1+IF(I4=1,0,Benefits_Load)) | O4: =IF(C4*Productive_Hours=0,0,N4/(C4*Productive_Hours)) | P4: =K4*E4*C4*L4*Productive_Hours
A5: R4 | B5: =IF(Anonymise=1,INDEX(Label_Anon,MATCH("R4",Label_Key,0)),INDEX(Label_Real,MATCH("R4",Label_Key,0))) | C5: 1 | D5: 0 | E5: 1 | F5: 0.35 | G5: 72000 | H5: OBSERVED | I5: 0 | K5: =IF(A5="R7",Consultant_Present,1) | L5: =IF(AND(A5="R4",Resp_Internal=1),Seat_Ops_Alloc,F5) | M5: =IF(AND(A5="R4",Resp_Internal=1),Ops_Seat_Comp,G5) | N5: =M5*(1+IF(I5=1,0,Benefits_Load)) | O5: =IF(C5*Productive_Hours=0,0,N5/(C5*Productive_Hours)) | P5: =K5*E5*C5*L5*Productive_Hours
A6: R5 | B6: =IF(Anonymise=1,INDEX(Label_Anon,MATCH("R5",Label_Key,0)),INDEX(Label_Real,MATCH("R5",Label_Key,0))) | C6: 1 | D6: 0 | E6: 1 | F6: 0.9 | G6: 58000 | H6: PLACEHOLDER | I6: 0 | K6: =IF(A6="R7",Consultant_Present,1) | L6: =IF(AND(A6="R4",Resp_Internal=1),Seat_Ops_Alloc,F6) | M6: =IF(AND(A6="R4",Resp_Internal=1),Ops_Seat_Comp,G6) | N6: =M6*(1+IF(I6=1,0,Benefits_Load)) | O6: =IF(C6*Productive_Hours=0,0,N6/(C6*Productive_Hours)) | P6: =K6*E6*C6*L6*Productive_Hours
A7: R6 | B7: =IF(Anonymise=1,INDEX(Label_Anon,MATCH("R6",Label_Key,0)),INDEX(Label_Real,MATCH("R6",Label_Key,0))) | C7: 1 | D7: 0 | E7: 1 | F7: 0.5 | G7: 68000 | H7: PLACEHOLDER | I7: 0 | K7: =IF(A7="R7",Consultant_Present,1) | L7: =IF(AND(A7="R4",Resp_Internal=1),Seat_Ops_Alloc,F7) | M7: =IF(AND(A7="R4",Resp_Internal=1),Ops_Seat_Comp,G7) | N7: =M7*(1+IF(I7=1,0,Benefits_Load)) | O7: =IF(C7*Productive_Hours=0,0,N7/(C7*Productive_Hours)) | P7: =K7*E7*C7*L7*Productive_Hours
A8: R7 | B8: =IF(Anonymise=1,INDEX(Label_Anon,MATCH("R7",Label_Key,0)),INDEX(Label_Real,MATCH("R7",Label_Key,0))) | C8: 0.38 | D8: 0 | E8: 1 | F8: 1 | G8: 78000 | H8: PLACEHOLDER | I8: 1 | J8: 2026-12-14 | K8: =IF(A8="R7",Consultant_Present,1) | L8: =IF(AND(A8="R4",Resp_Internal=1),Seat_Ops_Alloc,F8) | M8: =IF(AND(A8="R4",Resp_Internal=1),Ops_Seat_Comp,G8) | N8: =M8*(1+IF(I8=1,0,Benefits_Load)) | O8: =IF(C8*Productive_Hours=0,0,N8/(C8*Productive_Hours)) | P8: =K8*E8*C8*L8*Productive_Hours
B10: Total FTE | C10: =SUMPRODUCT(K2:K8,C2:C8) | O10: Operations hours available | P10: =SUM(P2:P8)+Extra_Ops_Fte*Productive_Hours
B12: Loaded $/hour divides by the role's OWN hours (FTE x productive hours), so a fractional role is not costed as though it were full time. Contractors carry no benefits load.

Sheet Book
A1: Tier | B1: Label | C1: Households | D1: Average AUM | E1: Accounts per household | F1: New-business mix | G1: Tag | H1: Total AUM | I1: Accounts in tier | J1: New households / yr | K1: Fee per household | L1: Revenue per household | M1: Revenue from tier
A2: T1 | B2: Under $250k | C2: 38 | D2: 118000 | E2: 1.6 | F2: 0.05 | G2: OBSERVED | H2: =C2*D2 | I2: =C2*E2 | J2: =Total_HH*Growth_Rate*F2 | K2: =SUMPRODUCT((D2>Fee_From)*(D2-Fee_From)*Fee_Delta) | L2: =K2*Fee_Realisation | M2: =C2*L2
A3: T2 | B3: $250k - $1m | C3: 74 | D3: 560000 | E3: 2.4 | F3: 0.25 | G3: OBSERVED | H3: =C3*D3 | I3: =C3*E3 | J3: =Total_HH*Growth_Rate*F3 | K3: =SUMPRODUCT((D3>Fee_From)*(D3-Fee_From)*Fee_Delta) | L3: =K3*Fee_Realisation | M3: =C3*L3
A4: T3 | B4: $1m - $3m | C4: 52 | D4: 1720000 | E4: 3.4 | F4: 0.45 | G4: OBSERVED | H4: =C4*D4 | I4: =C4*E4 | J4: =Total_HH*Growth_Rate*F4 | K4: =SUMPRODUCT((D4>Fee_From)*(D4-Fee_From)*Fee_Delta) | L4: =K4*Fee_Realisation | M4: =C4*L4
A5: T4 | B5: Over $3m | C5: 18 | D5: 5100000 | E5: 4.8 | F5: 0.25 | G5: OBSERVED | H5: =C5*D5 | I5: =C5*E5 | J5: =Total_HH*Growth_Rate*F5 | K5: =SUMPRODUCT((D5>Fee_From)*(D5-Fee_From)*Fee_Delta) | L5: =K5*Fee_Realisation | M5: =C5*L5
B6: Whole book | C6: =SUM(C2:C5) | H6: =SUM(H2:H5) | J6: =SUM(J2:J5) | M6: =SUM(M2:M5)
B8: Households and average AUM are the inputs; total AUM is a formula. Never put a single household on this sheet — if a figure would identify one, it is at the wrong grain.
B9: New-business mix must sum to 100%. | F9: =SUM(F2:F5)

Sheet FeeSchedule
A1: Band | B1: From | C1: To | D1: Rate | E1: Rate step (rate less previous rate)
A2: 1 | B2: 0 | C2: 500000 | D2: 0.01 | E2: =D2
A3: 2 | B3: 500000 | C3: 1000000 | D3: 0.0085 | E3: =D3-D2
A4: 3 | B4: 1000000 | C4: 3000000 | D4: 0.007 | E4: =D4-D3
A5: 4 | B5: 3000000 | C5: 5000000 | D5: 0.005 | E5: =D5-D4
A6: 5 | B6: 5000000 | C6: 1e+15 | D6: 0.0035 | E6: =D6-D5
A8: TIERED / MARGINAL | B8: TIERED / MARGINAL. Each band is charged at its own rate on the portion of assets falling inside that band. This is NOT a flat rate applied to total assets.
B9: The fee is computed as SUMPRODUCT((AUM>Fee_From)*(AUM-Fee_From)*Fee_Delta) — the rate-step form of a marginal schedule. It is mathematically identical to summing each band's own slice, and it survives adding or removing bands.
B10: The open top band's To is 1E+15 rather than blank, so the arithmetic has an upper bound.
A12: HAND CHECK — three households, worked on paper
A13: If any row below says FAIL, the schedule has been broken. The usual cause is turning a tiered schedule into a flat rate by accident.
A14: Case | B14: AUM | C14: Model says | D14: Hand-worked | E14: Check | F14: The working
A15: Below the first breakpoint | B15: 145000 | C15: =SUMPRODUCT((B15>Fee_From)*(B15-Fee_From)*Fee_Delta) | D15: 1450 | E15: =IF(ROUND(C15-D15,2)=0,"PASS","FAIL") | F15: 145,000 x 1.00% = 1,450.00
A16: Just above a breakpoint | B16: 520000 | C16: =SUMPRODUCT((B16>Fee_From)*(B16-Fee_From)*Fee_Delta) | D16: 5170 | E16: =IF(ROUND(C16-D16,2)=0,"PASS","FAIL") | F16: 500,000 x 1.00% = 5,000.00 + 20,000 x 0.85% = 170.00 = 5,170.00 (a flat 0.85% on the whole balance would give 4,420.00 — a $750 error, and the commonest mistake in these models)
A17: Well above | B17: 5100000 | C17: =SUMPRODUCT((B17>Fee_From)*(B17-Fee_From)*Fee_Delta) | D17: 33600 | E17: =IF(ROUND(C17-D17,2)=0,"PASS","FAIL") | F17: 500,000 x 1.00% = 5,000 + 500,000 x 0.85% = 4,250 + 2,000,000 x 0.70% = 14,000 + 2,000,000 x 0.50% = 10,000 + 100,000 x 0.35% = 350 = 33,600 (effective rate 0.659%)
A19: All three pass | E19: =IF(COUNTIF(E15:E17,"PASS")=3,"PASS","FAIL")

Sheet Tasks
A1: ID | B1: Task | C1: Trigger basis | D1: Minutes per occurrence | E1: Occurrences / yr | F1: Applies T1 | G1: Applies T2 | H1: Applies T3 | I1: Applies T4 | J1: Owner | K1: Work type | L1: Tag | M1: Minutes / yr | N1: Hours / yr
A2: F1 | B2: Daily custodian reconciliation | C2: firm | D2: 25 | E2: 250 | F2: 0 | G2: 0 | H2: 0 | I2: 0 | J2: R6 | K2: operations | L2: PLACEHOLDER | M2: =D2*Efficiency*E2*IF(C2="firm",1,IF(C2="household",F2*Book!$C$2+G2*Book!$C$3+H2*Book!$C$4+I2*Book!$C$5,IF(C2="account",F2*Book!$I$2+G2*Book!$I$3+H2*Book!$I$4+I2*Book!$I$5,F2*Book!$J$2+G2*Book!$J$3+H2*Book!$J$4+I2*Book!$J$5))) | N2: =M2/60*IF(K2="operations",1+Switching_Uplift,1)
A3: F2 | B3: Quarterly billing cycle: calculate, review, submit | C3: firm | D3: 240 | E3: 4 | F3: 0 | G3: 0 | H3: 0 | I3: 0 | J3: R7 | K3: operations | L3: PLACEHOLDER | M3: =D3*Efficiency*E3*IF(C3="firm",1,IF(C3="household",F3*Book!$C$2+G3*Book!$C$3+H3*Book!$C$4+I3*Book!$C$5,IF(C3="account",F3*Book!$I$2+G3*Book!$I$3+H3*Book!$I$4+I3*Book!$I$5,F3*Book!$J$2+G3*Book!$J$3+H3*Book!$J$4+I3*Book!$J$5))) | N3: =M3/60*IF(K3="operations",1+Switching_Uplift,1)
A4: F3 | B4: Billing exceptions, adjustments and refunds | C4: firm | D4: 90 | E4: 4 | F4: 0 | G4: 0 | H4: 0 | I4: 0 | J4: R7 | K4: operations | L4: PLACEHOLDER | M4: =D4*Efficiency*E4*IF(C4="firm",1,IF(C4="household",F4*Book!$C$2+G4*Book!$C$3+H4*Book!$C$4+I4*Book!$C$5,IF(C4="account",F4*Book!$I$2+G4*Book!$I$3+H4*Book!$I$4+I4*Book!$I$5,F4*Book!$J$2+G4*Book!$J$3+H4*Book!$J$4+I4*Book!$J$5))) | N4: =M4/60*IF(K4="operations",1+Switching_Uplift,1)
A5: F4 | B5: Compliance calendar items (books and records, testing) | C5: firm | D5: 180 | E5: 12 | F5: 0 | G5: 0 | H5: 0 | I5: 0 | J5: R7 | K5: operations | L5: PLACEHOLDER | M5: =D5*Efficiency*E5*IF(C5="firm",1,IF(C5="household",F5*Book!$C$2+G5*Book!$C$3+H5*Book!$C$4+I5*Book!$C$5,IF(C5="account",F5*Book!$I$2+G5*Book!$I$3+H5*Book!$I$4+I5*Book!$I$5,F5*Book!$J$2+G5*Book!$J$3+H5*Book!$J$4+I5*Book!$J$5))) | N5: =M5/60*IF(K5="operations",1+Switching_Uplift,1)
A6: F5 | B6: Annual ADV amendment, delivery and filing | C6: firm | D6: 480 | E6: 1 | F6: 0 | G6: 0 | H6: 0 | I6: 0 | J6: R7 | K6: operations | L6: PLACEHOLDER | M6: =D6*Efficiency*E6*IF(C6="firm",1,IF(C6="household",F6*Book!$C$2+G6*Book!$C$3+H6*Book!$C$4+I6*Book!$C$5,IF(C6="account",F6*Book!$I$2+G6*Book!$I$3+H6*Book!$I$4+I6*Book!$I$5,F6*Book!$J$2+G6*Book!$J$3+H6*Book!$J$4+I6*Book!$J$5))) | N6: =M6/60*IF(K6="operations",1+Switching_Uplift,1)
A7: F6 | B7: Vendor management (custodian, CRM, planning, e-sign) | C7: firm | D7: 120 | E7: 12 | F7: 0 | G7: 0 | H7: 0 | I7: 0 | J7: R7 | K7: operations | L7: PLACEHOLDER | M7: =D7*Efficiency*E7*IF(C7="firm",1,IF(C7="household",F7*Book!$C$2+G7*Book!$C$3+H7*Book!$C$4+I7*Book!$C$5,IF(C7="account",F7*Book!$I$2+G7*Book!$I$3+H7*Book!$I$4+I7*Book!$I$5,F7*Book!$J$2+G7*Book!$J$3+H7*Book!$J$4+I7*Book!$J$5))) | N7: =M7/60*IF(K7="operations",1+Switching_Uplift,1)
A8: F7 | B8: Quarterly performance reporting run | C8: firm | D8: 300 | E8: 4 | F8: 0 | G8: 0 | H8: 0 | I8: 0 | J8: R7 | K8: operations | L8: PLACEHOLDER | M8: =D8*Efficiency*E8*IF(C8="firm",1,IF(C8="household",F8*Book!$C$2+G8*Book!$C$3+H8*Book!$C$4+I8*Book!$C$5,IF(C8="account",F8*Book!$I$2+G8*Book!$I$3+H8*Book!$I$4+I8*Book!$I$5,F8*Book!$J$2+G8*Book!$J$3+H8*Book!$J$4+I8*Book!$J$5))) | N8: =M8/60*IF(K8="operations",1+Switching_Uplift,1)
A9: F8 | B9: CRM hygiene sweep (data audit, workflow cleanup) | C9: firm | D9: 120 | E9: 12 | F9: 0 | G9: 0 | H9: 0 | I9: 0 | J9: R4 | K9: operations | L9: PLACEHOLDER | M9: =D9*Efficiency*E9*IF(C9="firm",1,IF(C9="household",F9*Book!$C$2+G9*Book!$C$3+H9*Book!$C$4+I9*Book!$C$5,IF(C9="account",F9*Book!$I$2+G9*Book!$I$3+H9*Book!$I$4+I9*Book!$I$5,F9*Book!$J$2+G9*Book!$J$3+H9*Book!$J$4+I9*Book!$J$5))) | N9: =M9/60*IF(K9="operations",1+Switching_Uplift,1)
A10: F9 | B10: Trade error review and correction log | C10: firm | D10: 45 | E10: 12 | F10: 0 | G10: 0 | H10: 0 | I10: 0 | J10: R7 | K10: operations | L10: PLACEHOLDER | M10: =D10*Efficiency*E10*IF(C10="firm",1,IF(C10="household",F10*Book!$C$2+G10*Book!$C$3+H10*Book!$C$4+I10*Book!$C$5,IF(C10="account",F10*Book!$I$2+G10*Book!$I$3+H10*Book!$I$4+I10*Book!$I$5,F10*Book!$J$2+G10*Book!$J$3+H10*Book!$J$4+I10*Book!$J$5))) | N10: =M10/60*IF(K10="operations",1+Switching_Uplift,1)
A11: F10 | B11: Staff onboarding and offboarding (systems, access) | C11: firm | D11: 240 | E11: 2 | F11: 0 | G11: 0 | H11: 0 | I11: 0 | J11: R6 | K11: operations | L11: PLACEHOLDER | M11: =D11*Efficiency*E11*IF(C11="firm",1,IF(C11="household",F11*Book!$C$2+G11*Book!$C$3+H11*Book!$C$4+I11*Book!$C$5,IF(C11="account",F11*Book!$I$2+G11*Book!$I$3+H11*Book!$I$4+I11*Book!$I$5,F11*Book!$J$2+G11*Book!$J$3+H11*Book!$J$4+I11*Book!$J$5))) | N11: =M11/60*IF(K11="operations",1+Switching_Uplift,1)
A12: F11 | B12: Business continuity and cybersecurity review | C12: firm | D12: 240 | E12: 2 | F12: 0 | G12: 0 | H12: 0 | I12: 0 | J12: R7 | K12: operations | L12: PLACEHOLDER | M12: =D12*Efficiency*E12*IF(C12="firm",1,IF(C12="household",F12*Book!$C$2+G12*Book!$C$3+H12*Book!$C$4+I12*Book!$C$5,IF(C12="account",F12*Book!$I$2+G12*Book!$I$3+H12*Book!$I$4+I12*Book!$I$5,F12*Book!$J$2+G12*Book!$J$3+H12*Book!$J$4+I12*Book!$J$5))) | N12: =M12/60*IF(K12="operations",1+Switching_Uplift,1)
A13: F12 | B13: Operations standing agenda in the team meeting | C13: firm | D13: 30 | E13: 48 | F13: 0 | G13: 0 | H13: 0 | I13: 0 | J13: R6 | K13: operations | L13: PLACEHOLDER | M13: =D13*Efficiency*E13*IF(C13="firm",1,IF(C13="household",F13*Book!$C$2+G13*Book!$C$3+H13*Book!$C$4+I13*Book!$C$5,IF(C13="account",F13*Book!$I$2+G13*Book!$I$3+H13*Book!$I$4+I13*Book!$I$5,F13*Book!$J$2+G13*Book!$J$3+H13*Book!$J$4+I13*Book!$J$5))) | N13: =M13/60*IF(K13="operations",1+Switching_Uplift,1)
... A42: V5 | B42: Planning work and recommendations | C42: household | D42: 240 | E42: 1 | F42: 0 | G42: 0 | H42: 1 | I42: 1 | J42: R1 | K42: advisory | L42: PLACEHOLDER | M42: =D42*Efficiency*E42*IF(C42="firm",1,IF(C42="household",F42*Book!$C$2+G42*Book!$C$3+H42*Book!$C$4+I42*Book!$C$5,IF(C42="account",F42*Book!$I$2+G42*Book!$I$3+H42*Book!$I$4+I42*Book!$I$5,F42*Book!$J$2+G42*Book!$J$3+H42*Book!$J$4+I42*Book!$J$5))) | N42: =M42/60*IF(K42="operations",1+Switching_Uplift,1)
B44: Total operations hours a year | N44: =SUMPRODUCT((K2:K42="operations")*N2:N42)
B46: Every row is seeded PLACEHOLDER. The shape of the catalogue is real RIA operations work; the minutes are not. Replace each figure with a median of three timed runs and change the tag to MEASURED. That column is the strongest evidence in this model.

Sheet Engine
A1: ENGINE
A2: Every cell on this sheet is a formula. There are no typed numbers here — if one appears, it is a bug.
A5: RATES
A6: Blended operations $ per hour | B6: =IFERROR(SUMPRODUCT(Roster_OpsHours,Roster_Hourly)/SUM(Roster_OpsHours),0) | F6: Weighted by the hours each operations role actually gives to operations.
A7: Advisor loaded $ per hour | B7: =IFERROR(SUMPRODUCT(Roster_Adv,Roster_Active,Roster_Loaded)/(SUMPRODUCT(Roster_Adv,Roster_Active,Roster_FTE)*Productive_Hours),0) | F7: What an advisor hour COSTS. Used for case 4 on purpose.
A8: Revenue per advisor hour | B8: =IFERROR(Revenue_Total/(SUMPRODUCT(Roster_Adv,Roster_Active,Roster_FTE)*Productive_Hours),0) | F8: What an advisor hour EARNS. Larger, and it invites the challenge that the hour would not have been sold.
A10: BOOK AND REVENUE
A11: Total households | B11: =Total_HH
A12: Total AUM | B12: =AUM_Total
A13: New households per year | B13: =Total_HH*Growth_Rate
A14: Revenue at the fee schedule | B14: =Revenue_Total
A15: Revenue per household | B15: =IFERROR(Revenue_Total/Total_HH,0)
A16: Advisor count | B16: =SUMPRODUCT(Roster_Adv,Roster_Active)
A17: Revenue per advisor | B17: =IFERROR(Revenue_Total/B16,0)
A18: Revenue per employee (per FTE) | B18: =IFERROR(Revenue_Total/Total_FTE,0)
A20: OPERATIONS HOURS PER YEAR
A21: Recurring (household and account work) | B21: =SUMPRODUCT((Tasks_WT="operations")*((Tasks_Basis="household")+(Tasks_Basis="account"))*Tasks_Hours)
A22: Onboarding (scales with growth, not the book) | B22: =SUMPRODUCT((Tasks_WT="operations")*(Tasks_Basis="new_household")*Tasks_Hours)
A23: Firm-level (does not scale with households) | B23: =SUMPRODUCT((Tasks_WT="operations")*(Tasks_Basis="firm")*Tasks_Hours)
A24: TOTAL REQUIRED | B24: =B21+B22+B23
A25: TOTAL AVAILABLE | B25: =Ops_Hours_Available
A26: UTILISATION | B26: =IFERROR(B24/B25,0) | F26: Over 100% means there is more operations work than the operations team can hold.
A28: WHERE THE OPERATIONS WORK SITS TODAY
A29: Hours owned by R1 | B29: =SUMPRODUCT((Tasks_WT="operations")*(Tasks_Owner="R1")*Tasks_Hours)
A30: Hours owned by R2 | B30: =SUMPRODUCT((Tasks_WT="operations")*(Tasks_Owner="R2")*Tasks_Hours)
A31: Hours owned by R3 | B31: =SUMPRODUCT((Tasks_WT="operations")*(Tasks_Owner="R3")*Tasks_Hours)
A32: Hours owned by R4 | B32: =SUMPRODUCT((Tasks_WT="operations")*(Tasks_Owner="R4")*Tasks_Hours)
A33: Hours owned by R5 | B33: =SUMPRODUCT((Tasks_WT="operations")*(Tasks_Owner="R5")*Tasks_Hours)
A34: Hours owned by R6 | B34: =SUMPRODUCT((Tasks_WT="operations")*(Tasks_Owner="R6")*Tasks_Hours)
A35: Hours owned by R7 | B35: =SUMPRODUCT((Tasks_WT="operations")*(Tasks_Owner="R7")*Tasks_Hours)
A36: Operations work sitting on advisors | B36: =B29+B30+B31 | F36: Operations work an advisor currently does. This is what an operations seat moves.
A38: PER TIER
B39: T1 | C39: T2 | D39: T3 | E39: T4
A40: Share of the book | B40: =Book!C2/Total_HH | C40: =Book!C3/Total_HH | D40: =Book!C4/Total_HH | E40: =Book!C5/Total_HH
A41: Recurring operations minutes per household | B41: =SUMPRODUCT((Tasks_WT="operations")*(Tasks_Basis="household")*Tasks_A1*Tasks_Min*Efficiency*Tasks_Occ)+SUMPRODUCT((Tasks_WT="operations")*(Tasks_Basis="account")*Tasks_A1*Tasks_Min*Efficiency*Tasks_Occ)*Book!E2 | C41: =SUMPRODUCT((Tasks_WT="operations")*(Tasks_Basis="household")*Tasks_A2*Tasks_Min*Efficiency*Tasks_Occ)+SUMPRODUCT((Tasks_WT="operations")*(Tasks_Basis="account")*Tasks_A2*Tasks_Min*Efficiency*Tasks_Occ)*Book!E3 | D41: =SUMPRODUCT((Tasks_WT="operations")*(Tasks_Basis="household")*Tasks_A3*Tasks_Min*Efficiency*Tasks_Occ)+SUMPRODUCT((Tasks_WT="operations")*(Tasks_Basis="account")*Tasks_A3*Tasks_Min*Efficiency*Tasks_Occ)*Book!E4 | E41: =SUMPRODUCT((Tasks_WT="operations")*(Tasks_Basis="household")*Tasks_A4*Tasks_Min*Efficiency*Tasks_Occ)+SUMPRODUCT((Tasks_WT="operations")*(Tasks_Basis="account")*Tasks_A4*Tasks_Min*Efficiency*Tasks_Occ)*Book!E5
A42: Onboarding operations minutes per new household | B42: =SUMPRODUCT((Tasks_WT="operations")*(Tasks_Basis="new_household")*Tasks_A1*Tasks_Min*Efficiency*Tasks_Occ) | C42: =SUMPRODUCT((Tasks_WT="operations")*(Tasks_Basis="new_household")*Tasks_A2*Tasks_Min*Efficiency*Tasks_Occ) | D42: =SUMPRODUCT((Tasks_WT="operations")*(Tasks_Basis="new_household")*Tasks_A3*Tasks_Min*Efficiency*Tasks_Occ) | E42: =SUMPRODUCT((Tasks_WT="operations")*(Tasks_Basis="new_household")*Tasks_A4*Tasks_Min*Efficiency*Tasks_Occ)
A43: Advisory minutes per household | B43: =SUMPRODUCT((Tasks_WT="advisory")*(Tasks_Basis="household")*Tasks_A1*Tasks_Min*Efficiency*Tasks_Occ)+SUMPRODUCT((Tasks_WT="advisory")*(Tasks_Basis="account")*Tasks_A1*Tasks_Min*Efficiency*Tasks_Occ)*Book!E2 | C43: =SUMPRODUCT((Tasks_WT="advisory")*(Tasks_Basis="household")*Tasks_A2*Tasks_Min*Efficiency*Tasks_Occ)+SUMPRODUCT((Tasks_WT="advisory")*(Tasks_Basis="account")*Tasks_A2*Tasks_Min*Efficiency*Tasks_Occ)*Book!E3 | D43: =SUMPRODUCT((Tasks_WT="advisory")*(Tasks_Basis="household")*Tasks_A3*Tasks_Min*Efficiency*Tasks_Occ)+SUMPRODUCT((Tasks_WT="advisory")*(Tasks_Basis="account")*Tasks_A3*Tasks_Min*Efficiency*Tasks_Occ)*Book!E4 | E43: =SUMPRODUCT((Tasks_WT="advisory")*(Tasks_Basis="household")*Tasks_A4*Tasks_Min*Efficiency*Tasks_Occ)+SUMPRODUCT((Tasks_WT="advisory")*(Tasks_Basis="account")*Tasks_A4*Tasks_Min*Efficiency*Tasks_Occ)*Book!E5 | F43: Advisory work never counts against operations capacity. It is here only for the fully loaded cost to serve.
A44: Direct operations hours per household | B44: =B41/60*(1+Switching_Uplift) | C44: =C41/60*(1+Switching_Uplift) | D44: =D41/60*(1+Switching_Uplift) | E44: =E41/60*(1+Switching_Uplift)
A45: Layer 1 — direct operations cost | B45: =B44*B6 | C45: =C44*B6 | D45: =D44*B6 | E45: =E44*B6
A46: Layer 2 — share of firm-level operations | B46: =IFERROR(B23*B6/Total_HH,0) | C46: =IFERROR(B23*B6/Total_HH,0) | D46: =IFERROR(B23*B6/Total_HH,0) | E46: =IFERROR(B23*B6/Total_HH,0)
...

Sheet Case1_Departure
A1: CASE 1 — WHAT HAPPENS IN 100 DAYS
A2: The consultant's departure. The most urgent of the four and the only one with a date already on it.
A4: Days until she leaves | B4: =Departure_Days
A5: Which is | B5: =As_Of+Departure_Days
A6: Hours a year the catalogue has captured for her | B6: =Engine!B35
A7: Hours a year she is contracted for | B7: =Roster!C8*Productive_Hours
A8: Hours the catalogue has NOT captured | B8: =MAX(0,B7-B6) | F8: Almost certainly real work not yet written down, not slack. Everything below understates the problem by this much.
A10: BASE HOURS (read from the roster, independent of the scenario switch)
A11: Operations hours available with her here | B11: =SUMPRODUCT(Roster!E2:E8,Roster!C2:C8,Roster!F2:F8)*Productive_Hours+Extra_Ops_Fte*Productive_Hours
A12: of which hers | B12: =Roster!C8*Roster!F8*Productive_Hours
A13: my operations hours today | B13: =Roster!C5*Roster!F5*Productive_Hours
A14: my operations hours in the seat | B14: =Roster!C5*Seat_Ops_Alloc*Productive_Hours
A15: Operations hours required (unchanged by who does them) | B15: =Engine!B24
A17: THE THREE PLACES HER HOURS CAN GO
A18: Response | B18: Annual cost | C18: Hours available after | D18: Utilisation after | E18: Hours left with no owner | F18: What it costs elsewhere
A19: Absorb across the existing team | B19: =0 | C19: =B11-B12 | D19: =IFERROR(B15/C19,0) | E19: =MAX(0,B15-C19) | F19: No new spend. The hours land on the people already here.
A20: Backfill with a like-for-like hire | B20: =Backfill_Cost | C20: =B11-B12+Roster!C8*Productive_Hours | D20: =IFERROR(B15/C20,0) | E20: =MAX(0,B15-C20) | F20: Replaces her hours at the same cost. Break-even is immediate by construction; the question is whether the hours come back.
A21: I take it on | B21: =(Ops_Seat_Comp-Roster!G5)*(1+Benefits_Load) | C21: =B11-B12+B14-B13 | D21: =IFERROR(B15/C21,0) | E21: =MAX(0,B15-C21) | F21: Compensation delta only, loaded. Displaces paraplanning work that has to go somewhere — see Case4.
A23: THE SENTENCE THIS ENDS ON
A24: ="When she leaves, "&TEXT(B6,"#,##0")&" catalogued hours a year need a home — and "&TEXT(B8,"#,##0")&" more that this model cannot see yet. Absorbing them puts operations at "&TEXT(D19,"0.0%")&" and leaves "&TEXT(E19,"#,##0")&" hours with nobody on them."

Sheet Case2_Capacity
A1: CASE 2 — WHERE CAPACITY BREAKS
A2: Month by month. New households enter by the new-business mix, so the tier mix shifts as the book grows.
A3: Monthly growth rate | B3: =(1+Growth_Rate)^(1/12)-1
A5: Month | B5: Date | C5: Households T1 | D5: Households T2 | E5: Households T3 | F5: Households T4 | G5: Total households | H5: New / yr | I5: Hours required | J5: Hours available | K5: Utilisation | L5: Over? | M5: Over with seat?
A6: 0 | B6: =As_Of+ROUND(A6*30.4375,0) | C6: =Book!C2 | D6: =Book!C3 | E6: =Book!C4 | F6: =Book!C5 | G6: =SUM(C6:F6) | H6: =G6*Growth_Rate | I6: =(SUMPRODUCT(C6:F6,Engine!$B$41:$E$41)+H6*(Engine!$B$42*Book!$F$2+Engine!$C$42*Book!$F$3+Engine!$D$42*Book!$F$4+Engine!$E$42*Book!$F$5))/60*(1+Switching_Uplift)+Engine!$B$23 | J6: =Engine!$B$25 | K6: =IFERROR(I6/J6,0) | L6: =IF(I6>=J6,1,0) | M6: =IF(I6>=C1_Internal_Avail,1,0)
A7: 1 | B7: =As_Of+ROUND(A7*30.4375,0) | C7: =C6+G6*Monthly_Growth*Book!$F$2 | D7: =D6+G6*Monthly_Growth*Book!$F$3 | E7: =E6+G6*Monthly_Growth*Book!$F$4 | F7: =F6+G6*Monthly_Growth*Book!$F$5 | G7: =SUM(C7:F7) | H7: =G7*Growth_Rate | I7: =(SUMPRODUCT(C7:F7,Engine!$B$41:$E$41)+H7*(Engine!$B$42*Book!$F$2+Engine!$C$42*Book!$F$3+Engine!$D$42*Book!$F$4+Engine!$E$42*Book!$F$5))/60*(1+Switching_Uplift)+Engine!$B$23 | J7: =Engine!$B$25 | K7: =IFERROR(I7/J7,0) | L7: =IF(I7>=J7,1,0) | M7: =IF(I7>=C1_Internal_Avail,1,0)
A8: 2 | B8: =As_Of+ROUND(A8*30.4375,0) | C8: =C7+G7*Monthly_Growth*Book!$F$2 | D8: =D7+G7*Monthly_Growth*Book!$F$3 | E8: =E7+G7*Monthly_Growth*Book!$F$4 | F8: =F7+G7*Monthly_Growth*Book!$F$5 | G8: =SUM(C8:F8) | H8: =G8*Growth_Rate | I8: =(SUMPRODUCT(C8:F8,Engine!$B$41:$E$41)+H8*(Engine!$B$42*Book!$F$2+Engine!$C$42*Book!$F$3+Engine!$D$42*Book!$F$4+Engine!$E$42*Book!$F$5))/60*(1+Switching_Uplift)+Engine!$B$23 | J8: =Engine!$B$25 | K8: =IFERROR(I8/J8,0) | L8: =IF(I8>=J8,1,0) | M8: =IF(I8>=C1_Internal_Avail,1,0)
A9: 3 | B9: =As_Of+ROUND(A9*30.4375,0) | C9: =C8+G8*Monthly_Growth*Book!$F$2 | D9: =D8+G8*Monthly_Growth*Book!$F$3 | E9: =E8+G8*Monthly_Growth*Book!$F$4 | F9: =F8+G8*Monthly_Growth*Book!$F$5 | G9: =SUM(C9:F9) | H9: =G9*Growth_Rate | I9: =(SUMPRODUCT(C9:F9,Engine!$B$41:$E$41)+H9*(Engine!$B$42*Book!$F$2+Engine!$C$42*Book!$F$3+Engine!$D$42*Book!$F$4+Engine!$E$42*Book!$F$5))/60*(1+Switching_Uplift)+Engine!$B$23 | J9: =Engine!$B$25 | K9: =IFERROR(I9/J9,0) | L9: =IF(I9>=J9,1,0) | M9: =IF(I9>=C1_Internal_Avail,1,0)
A10: 4 | B10: =As_Of+ROUND(A10*30.4375,0) | C10: =C9+G9*Monthly_Growth*Book!$F$2 | D10: =D9+G9*Monthly_Growth*Book!$F$3 | E10: =E9+G9*Monthly_Growth*Book!$F$4 | F10: =F9+G9*Monthly_Growth*Book!$F$5 | G10: =SUM(C10:F10) | H10: =G10*Growth_Rate | I10: =(SUMPRODUCT(C10:F10,Engine!$B$41:$E$41)+H10*(Engine!$B$42*Book!$F$2+Engine!$C$42*Book!$F$3+Engine!$D$42*Book!$F$4+Engine!$E$42*Book!$F$5))/60*(1+Switching_Uplift)+Engine!$B$23 | J10: =Engine!$B$25 | K10: =IFERROR(I10/J10,0) | L10: =IF(I10>=J10,1,0) | M10: =IF(I10>=C1_Internal_Avail,1,0)
A11: 5 | B11: =As_Of+ROUND(A11*30.4375,0) | C11: =C10+G10*Monthly_Growth*Book!$F$2 | D11: =D10+G10*Monthly_Growth*Book!$F$3 | E11: =E10+G10*Monthly_Growth*Book!$F$4 | F11: =F10+G10*Monthly_Growth*Book!$F$5 | G11: =SUM(C11:F11) | H11: =G11*Growth_Rate | I11: =(SUMPRODUCT(C11:F11,Engine!$B$41:$E$41)+H11*(Engine!$B$42*Book!$F$2+Engine!$C$42*Book!$F$3+Engine!$D$42*Book!$F$4+Engine!$E$42*Book!$F$5))/60*(1+Switching_Uplift)+Engine!$B$23 | J11: =Engine!$B$25 | K11: =IFERROR(I11/J11,0) | L11: =IF(I11>=J11,1,0) | M11: =IF(I11>=C1_Internal_Avail,1,0)
A12: 6 | B12: =As_Of+ROUND(A12*30.4375,0) | C12: =C11+G11*Monthly_Growth*Book!$F$2 | D12: =D11+G11*Monthly_Growth*Book!$F$3 | E12: =E11+G11*Monthly_Growth*Book!$F$4 | F12: =F11+G11*Monthly_Growth*Book!$F$5 | G12: =SUM(C12:F12) | H12: =G12*Growth_Rate | I12: =(SUMPRODUCT(C12:F12,Engine!$B$41:$E$41)+H12*(Engine!$B$42*Book!$F$2+Engine!$C$42*Book!$F$3+Engine!$D$42*Book!$F$4+Engine!$E$42*Book!$F$5))/60*(1+Switching_Uplift)+Engine!$B$23 | J12: =Engine!$B$25 | K12: =IFERROR(I12/J12,0) | L12: =IF(I12>=J12,1,0) | M12: =IF(I12>=C1_Internal_Avail,1,0)
A13: 7 | B13: =As_Of+ROUND(A13*30.4375,0) | C13: =C12+G12*Monthly_Growth*Book!$F$2 | D13: =D12+G12*Monthly_Growth*Book!$F$3 | E13: =E12+G12*Monthly_Growth*Book!$F$4 | F13: =F12+G12*Monthly_Growth*Book!$F$5 | G13: =SUM(C13:F13) | H13: =G13*Growth_Rate | I13: =(SUMPRODUCT(C13:F13,Engine!$B$41:$E$41)+H13*(Engine!$B$42*Book!$F$2+Engine!$C$42*Book!$F$3+Engine!$D$42*Book!$F$4+Engine!$E$42*Book!$F$5))/60*(1+Switching_Uplift)+Engine!$B$23 | J13: =Engine!$B$25 | K13: =IFERROR(I13/J13,0) | L13: =IF(I13>=J13,1,0) | M13: =IF(I13>=C1_Internal_Avail,1,0)
A14: 8 | B14: =As_Of+ROUND(A14*30.4375,0) | C14: =C13+G13*Monthly_Growth*Book!$F$2 | D14: =D13+G13*Monthly_Growth*Book!$F$3 | E14: =E13+G13*Monthly_Growth*Book!$F$4 | F14: =F13+G13*Monthly_Growth*Book!$F$5 | G14: =SUM(C14:F14) | H14: =G14*Growth_Rate | I14: =(SUMPRODUCT(C14:F14,Engine!$B$41:$E$41)+H14*(Engine!$B$42*Book!$F$2+Engine!$C$42*Book!$F$3+Engine!$D$42*Book!$F$4+Engine!$E$42*Book!$F$5))/60*(1+Switching_Uplift)+Engine!$B$23 | J14: =Engine!$B$25 | K14: =IFERROR(I14/J14,0) | L14: =IF(I14>=J14,1,0) | M14: =IF(I14>=C1_Internal_Avail,1,0)
A15: 9 | B15: =As_Of+ROUND(A15*30.4375,0) | C15: =C14+G14*Monthly_Growth*Book!$F$2 | D15: =D14+G14*Monthly_Growth*Book!$F$3 | E15: =E14+G14*Monthly_Growth*Book!$F$4 | F15: =F14+G14*Monthly_Growth*Book!$F$5 | G15: =SUM(C15:F15) | H15: =G15*Growth_Rate | I15: =(SUMPRODUCT(C15:F15,Engine!$B$41:$E$41)+H15*(Engine!$B$42*Book!$F$2+Engine!$C$42*Book!$F$3+Engine!$D$42*Book!$F$4+Engine!$E$42*Book!$F$5))/60*(1+Switching_Uplift)+Engine!$B$23 | J15: =Engine!$B$25 | K15: =IFERROR(I15/J15,0) | L15: =IF(I15>=J15,1,0) | M15: =IF(I15>=C1_Internal_Avail,1,0)
A16: 10 | B16: =As_Of+ROUND(A16*30.4375,0) | C16: =C15+G15*Monthly_Growth*Book!$F$2 | D16: =D15+G15*Monthly_Growth*Book!$F$3 | E16: =E15+G15*Monthly_Growth*Book!$F$4 | F16: =F15+G15*Monthly_Growth*Book!$F$5 | G16: =SUM(C16:F16) | H16: =G16*Growth_Rate | I16: =(SUMPRODUCT(C16:F16,Engine!$B$41:$E$41)+H16*(Engine!$B$42*Book!$F$2+Engine!$C$42*Book!$F$3+Engine!$D$42*Book!$F$4+Engine!$E$42*Book!$F$5))/60*(1+Switching_Uplift)+Engine!$B$23 | J16: =Engine!$B$25 | K16: =IFERROR(I16/J16,0) | L16: =IF(I16>=J16,1,0) | M16: =IF(I16>=C1_Internal_Avail,1,0)
A17: 11 | B17: =As_Of+ROUND(A17*30.4375,0) | C17: =C16+G16*Monthly_Growth*Book!$F$2 | D17: =D16+G16*Monthly_Growth*Book!$F$3 | E17: =E16+G16*Monthly_Growth*Book!$F$4 | F17: =F16+G16*Monthly_Growth*Book!$F$5 | G17: =SUM(C17:F17) | H17: =G17*Growth_Rate | I17: =(SUMPRODUCT(C17:F17,Engine!$B$41:$E$41)+H17*(Engine!$B$42*Book!$F$2+Engine!$C$42*Book!$F$3+Engine!$D$42*Book!$F$4+Engine!$E$42*Book!$F$5))/60*(1+Switching_Uplift)+Engine!$B$23 | J17: =Engine!$B$25 | K17: =IFERROR(I17/J17,0) | L17: =IF(I17>=J17,1,0) | M17: =IF(I17>=C1_Internal_Avail,1,0)
A18: 12 | B18: =As_Of+ROUND(A18*30.4375,0) | C18: =C17+G17*Monthly_Growth*Book!$F$2 | D18: =D17+G17*Monthly_Growth*Book!$F$3 | E18: =E17+G17*Monthly_Growth*Book!$F$4 | F18: =F17+G17*Monthly_Growth*Book!$F$5 | G18: =SUM(C18:F18) | H18: =G18*Growth_Rate | I18: =(SUMPRODUCT(C18:F18,Engine!$B$41:$E$41)+H18*(Engine!$B$42*Book!$F$2+Engine!$C$42*Book!$F$3+Engine!$D$42*Book!$F$4+Engine!$E$42*Book!$F$5))/60*(1+Switching_Uplift)+Engine!$B$23 | J18: =Engine!$B$25 | K18: =IFERROR(I18/J18,0) | L18: =IF(I18>=J18,1,0) | M18: =IF(I18>=C1_Internal_Avail,1,0)
... A78: 72 | B78: =As_Of+ROUND(A78*30.4375,0) | C78: =C77+G77*Monthly_Growth*Book!$F$2 | D78: =D77+G77*Monthly_Growth*Book!$F$3 | E78: =E77+G77*Monthly_Growth*Book!$F$4 | F78: =F77+G77*Monthly_Growth*Book!$F$5 | G78: =SUM(C78:F78) | H78: =G78*Growth_Rate | I78: =(SUMPRODUCT(C78:F78,Engine!$B$41:$E$41)+H78*(Engine!$B$42*Book!$F$2+Engine!$C$42*Book!$F$3+Engine!$D$42*Book!$F$4+Engine!$E$42*Book!$F$5))/60*(1+Switching_Uplift)+Engine!$B$23 | J78: =Engine!$B$25 | K78: =IFERROR(I78/J78,0) | L78: =IF(I78>=J78,1,0) | M78: =IF(I78>=C1_Internal_Avail,1,0)
A80: THE CROSSING
A81: First month at or over capacity (position in the table) | E81: =IFERROR(MATCH(1,Proj_Flag,0),0)
A82: Crossing, in months from today | E82: =IF(E81=0,"",IF(E81=1,0,(E81-2)+(Engine!$B$25-INDEX(Proj_Req,E81-1))/(INDEX(Proj_Req,E81)-INDEX(Proj_Req,E81-1))))
A83: Households at the crossing | E83: =IF(E81=0,"",IF(E81=1,INDEX(Proj_HH,1),INDEX(Proj_HH,E81-1)+(E82-(E81-2))*(INDEX(Proj_HH,E81)-INDEX(Proj_HH,E81-1))))
A84: Which is around | E84: =IF(E81=0,"",As_Of+ROUND(E82*30.4375,0))
A85: Utilisation today | E85: =Engine!B26
A87: SENSITIVITY OF THE DATE — change Growth_Rate on Assumptions and watch these three move together.
A88: Closed form at today's tier mix (hand-checkable) | E88: =Engine!B58 | G88: Higher than the projection above, because the projection sends most new households into the larger tiers, which cost more hours each.
A89: THE SENTENCE THIS ENDS ON
A90: =IF(E81=0,"At this growth rate operations does not run out of capacity inside the horizon.","At "&TEXT(Growth_Rate,"0%")&" growth, operations runs out of capacity at "&TEXT(E83,"#,##0")&" households, around "&TEXT(E84,"mmmm yyyy")&" — "&TEXT(E82,"#,##0")&" months from now.")

Sheet Case3_CostToServe
A1: CASE 3 — WHAT EACH CLIENT TIER COSTS TO SERVE
A2: Presented as a question. This is not a finding about any client, and it is not a recommendation.
A3: WARNING | B3: ="The largest layer below is non-payroll firm overhead at "&TEXT(Firm_Overhead_PH,"$#,##0")&" per household. That number is a PLACEHOLDER — it was invented so the model would run. It decides on its own whether the bottom tier looks profitable. Get the real figure before presenting this tab."
A5: Per household per year | B5: T1 | C5: T2 | D5: T3 | E5: T4 | F5: Whole book | G5: Note
A6: Households | B6: =Book!C2 | C6: =Book!C3 | D6: =Book!C4 | E6: =Book!C5 | F6: =Total_HH
A7: Average AUM | B7: =Book!D2 | C7: =Book!D3 | D7: =Book!D4 | E7: =Book!D5 | F7: =IFERROR(AUM_Total/Total_HH,0)
A8: Revenue per household | B8: =Engine!B50 | C8: =Engine!C50 | D8: =Engine!D50 | E8: =Engine!E50 | F8: =IFERROR((B8*Book!C2+C8*Book!C3+D8*Book!C4+E8*Book!C5)/Total_HH,0) | G8: At the tiered schedule, after fee realisation.
A9: Direct operations hours | B9: =Engine!B44 | C9: =Engine!C44 | D9: =Engine!D44 | E9: =Engine!E44 | F9: =IFERROR((B9*Book!C2+C9*Book!C3+D9*Book!C4+E9*Book!C5)/Total_HH,0) | G9: From the task catalogue. The only layer built from timings.
A10: Layer 1 — direct operations cost | B10: =Engine!B45 | C10: =Engine!C45 | D10: =Engine!D45 | E10: =Engine!E45 | F10: =IFERROR((B10*Book!C2+C10*Book!C3+D10*Book!C4+E10*Book!C5)/Total_HH,0)
A11: Layer 2 — share of firm-level operations | B11: =Engine!B46 | C11: =Engine!C46 | D11: =Engine!D46 | E11: =Engine!E46 | F11: =IFERROR((B11*Book!C2+C11*Book!C3+D11*Book!C4+E11*Book!C5)/Total_HH,0) | G11: Firm-level operations hours spread evenly.
A12: Layer 3 — advisor time | B12: =Engine!B47 | C12: =Engine!C47 | D12: =Engine!D47 | E12: =Engine!E47 | F12: =IFERROR((B12*Book!C2+C12*Book!C3+D12*Book!C4+E12*Book!C5)/Total_HH,0) | G12: Advisory work at what an advisor hour costs.
A13: Layer 4 — non-payroll firm overhead | B13: =Engine!B48 | C13: =Engine!C48 | D13: =Engine!D48 | E13: =Engine!E48 | F13: =IFERROR((B13*Book!C2+C13*Book!C3+D13*Book!C4+E13*Book!C5)/Total_HH,0) | G13: PLACEHOLDER. This is the layer that decides the answer.
A14: Fully loaded cost to serve | B14: =Engine!B49 | C14: =Engine!C49 | D14: =Engine!D49 | E14: =Engine!E49 | F14: =IFERROR((B14*Book!C2+C14*Book!C3+D14*Book!C4+E14*Book!C5)/Total_HH,0)
A15: Margin, fully loaded | B15: =Engine!B51 | C15: =Engine!C51 | D15: =Engine!D51 | E15: =Engine!E51 | F15: =IFERROR((B15*Book!C2+C15*Book!C3+D15*Book!C4+E15*Book!C5)/Total_HH,0)
A16: Margin on direct operations cost alone | B16: =Engine!B52 | C16: =Engine!C52 | D16: =Engine!D52 | E16: =Engine!E52 | F16: =IFERROR((B16*Book!C2+C16*Book!C3+D16*Book!C4+E16*Book!C5)/Total_HH,0) | G16: Positive here and negative above means the gap is created by overhead and advisor time, not by operations.
A17: Onboarding cost per new household (one-off) | B17: =Engine!B53 | C17: =Engine!C53 | D17: =Engine!D53 | E17: =Engine!E53 | F17: =IFERROR((B17*Book!C2+C17*Book!C3+D17*Book!C4+E17*Book!C5)/Total_HH,0) | G17: Deliberately excluded from cost to serve. Smearing it across the settled book would overstate every tier.
A19: THE THREE VERSIONS OF THIS DECISION — laid out flat on purpose. The model has no view on which is right.
A20: 1. Raise the minimum | B20: Stop taking households below a threshold. Protects capacity and margin. Costs the firm its pipeline: a small household today is sometimes a large one in ten years, and referrals come from families, not balances.
A21: 2. Serve that tier differently | B21: Keep them, change the service model: fewer scheduled meetings, group or digital review, a defined service tier. Cuts the operations hours each household takes. Costs consistency, and someone has to tell them.
A22: 3. Accept it as a pipeline cost | B22: Decide the shortfall is what the firm pays for relationships, referrals and the next generation. Perfectly defensible — but it should be a decision somebody made, not an accident of never having counted.
A24: THE SENTENCE THIS ENDS ON
A25: ="The bottom tier costs roughly "&TEXT(B14,"$#,##0")&" a year to serve on a fully loaded basis and produces "&TEXT(B8,"$#,##0")&". That is a decision, not a finding, and there are three versions of it above."

Sheet Case4_Seat
A1: CASE 4 — THE OPERATIONS SEAT
A2: An operations seat does not generate revenue. It protects advisor capacity and prevents service failures. That is the whole claim.
A4: Compensation delta for the seat | B4: =Ops_Seat_Comp-Roster!G5
A5: Cost of the seat, loaded | B5: =B4*(1+Benefits_Load)
A7: BLENDED OPERATIONS RATE AFTER SHE GOES AND I TAKE THE SEAT
A8: Operations role after the change | B8: Hours | C8: Loaded $/hour | D8: Hours x rate
A9: =Roster!B5 | B9: =Roster!C5*Seat_Ops_Alloc*Productive_Hours | C9: =IFERROR(Ops_Seat_Comp*(1+IF(Roster!I5=1,0,Benefits_Load))/(Roster!C5*Productive_Hours),0) | D9: =B9*C9
A10: =Roster!B6 | B10: =Roster!C6*Roster!F6*Productive_Hours | C10: =IFERROR(Roster!G6*(1+IF(Roster!I6=1,0,Benefits_Load))/(Roster!C6*Productive_Hours),0) | D10: =B10*C10
A11: =Roster!B7 | B11: =Roster!C7*Roster!F7*Productive_Hours | C11: =IFERROR(Roster!G7*(1+IF(Roster!I7=1,0,Benefits_Load))/(Roster!C7*Productive_Hours),0) | D11: =B11*C11
A12: Blended rate after the change | B12: =SUM(B9:B11) | C12: =IFERROR(SUM(D9:D11)/SUM(B9:B11),0)
A14: WHAT THE SEAT PROTECTS
A15: Component | B15: Hours | C15: Valued at | D15: Value per year | F15: Note
A16: Operations hours she leaves behind, covered in-house | B16: =C1_Catalogued | C16: =C12 | D16: =B16*C16
A17: Operations work currently sitting on advisors, moved off | B17: =Engine!B36 | C17: =Engine!B7 | D17: =B17*C17 | F17: Valued at what an advisor hour COSTS, not what it earns. The larger number invites the challenge that the hour would not have been sold.
A18: Service failures avoided | B18: =Failures_Avoided | C18: =Failure_Cost | D18: =B18*C18 | F18: Deliberately zero. No incident list, so nothing is counted. Raise it only against incidents somebody can name.
A19: Total protected | D19: =SUM(D16:D18)
A20: Cost of the seat, loaded | D20: =C4_SeatCost
A21: Surplus | D21: =D19-C4_SeatCost
A22: Cover ratio | D22: =IFERROR(D19/C4_SeatCost,0)
A24: WHAT IT COSTS ELSEWHERE — the hole in my own proposal
A25: Paraplanning hours displaced by the seat | B25: =(Seat_Ops_Alloc-Roster!F5)*Roster!C5*Productive_Hours | F25: The seat frees this many operations hours by moving my week — and displaces exactly the same number of paraplanning hours. That work does not disappear.
A26: if advisors absorb it | B26: =B25*Engine!B7 | F26: At this cost the proposal is worse than doing nothing. This is the question to put to him.
A27: if a junior seat absorbs it | B27: =IFERROR(Para_Backfill_Comp*(1+Benefits_Load)*B25/Productive_Hours,0)
A28: if the firm decides some of it stops | B28: free, but somebody has to choose
A29: Capacity headroom the seat buys | B29: =IFERROR(MATCH(1,Proj_FlagSeat,0)-1,"beyond the horizon") | C29: months
A31: THE SENTENCE THIS ENDS ON
A32: ="The seat costs "&TEXT(C4_SeatCost,"$#,##0")&" loaded. It has to protect "&TEXT(C4_SeatCost,"$#,##0")&" to pay for itself. On these numbers it protects "&TEXT(D19,"$#,##0")&" — but only if the "&TEXT(B25,"#,##0")&" hours of planning work it displaces are not simply handed back to the advisors."

Sheet Dashboard
A1: OPERATIONS CAPACITY & ECONOMICS
A2: ="Working model · as of "&TEXT(As_Of,"d mmmm yyyy")&" · scenario: "&Assumptions!C6
A3: ="Of "&Ledger_Count&" inputs, "&Ledger_Placeholders&" are still placeholders — numbers invented so the model would run. Treat any figure resting on one as a structure, not a finding."
A5: THE BOOK
A6: Households | B6: =Total_HH
A7: Assets under management | B7: =AUM_Total
A8: Revenue at the fee schedule | B8: =Revenue_Total
A9: Revenue per household | B9: =Engine!B15
A10: Revenue per advisor | B10: =Engine!B17
A11: Revenue per employee | B11: =Engine!B18
A13: OPERATIONS TODAY
A14: Hours required per year | B14: =Engine!B24
A15: Hours available per year | B15: =Engine!B25
A16: Utilisation | B16: =Engine!B26
A17: Operations work sitting on advisors | B17: =Engine!B36
A19: THE FOUR CASES
A20: 1 · Catalogued hours her departure leaves behind | B20: =C1_Catalogued
A21: 1 · Hours it has not captured | B21: =C1_Unmapped
A22: 1 · Utilisation if the team absorbs them | B22: =C1_Absorb_Util
A23: 2 · Households at the capacity crossing | B23: =C2_BreakHH
A24: 2 · Which is around | B24: =C2_BreakDate
A25: 3 · Bottom tier, fully loaded cost to serve | B25: =Case3_CostToServe!B14
A26: 3 · Bottom tier, revenue | B26: =Case3_CostToServe!B8
A27: 3 · Bottom tier, margin | B27: =Case3_CostToServe!B15
A28: 4 · Cost of the operations seat, loaded | B28: =C4_SeatCost
A29: 4 · What it protects | B29: =Case4_Seat!D19
A30: 4 · Surplus | B30: =Case4_Seat!D21
A33: TIER ECONOMICS (chart source)
A34: Tier | B34: Revenue per household | C34: Fully loaded cost to serve
A35: =Book!A2&" "&Book!B2 | B35: =Engine!B50 | C35: =Engine!B49
A36: =Book!A3&" "&Book!B3 | B36: =Engine!C50 | C36: =Engine!C49
A37: =Book!A4&" "&Book!B4 | B37: =Engine!D50 | C37: =Engine!D49
A38: =Book!A5&" "&Book!B5 | B38: =Engine!E50 | C38: =Engine!E49
